---
id: 异步解决方案
title: 异步解决方案
author: 李川
author_title: 随便写写
author_url: https://github.com/newlichuan
author_image_url: /img/logo.jpg
---

#### 异步解决方案....

<!--truncate-->

## 什么是异步

首先,JS 本身是没有异步这个概念的,但是搭配宿主环境可以实现异步方式的并行运行方式  
虽然 v8 是单线程的,但是浏览器是多线程的,像定时器,AJAX,读写文件等,这些都不是运行在 V8 引擎中的,而是浏览器单独的线程,所以引擎有能力做到无需等待此类任务执行完毕,只需要做到执行完毕时将回调函数放入任务队列就行,任务队列也是浏览器提供的,而非存在与 ECMA 规范中,所以我们说的异步方式,就是这些宿主环境提供的,可以后台执行的任务,被包装成一个事件的方式来处理的任务

```js
setTimeOut(() => console.log(123), 1000);
```

如上面这个例子,定时器是独立于 js 线程执行的,所以会在事件完成后将任务放入事件队列 供引擎空闲时调用

## 管理异步

既然有此类任务,我们自然需要在任务完成时去下一件事情,连接多个任务,就成了我们需要处理的问题了  
管理这些异步任务,目前有三种解决方案

### 1. 回调函数

最简单的方式,只有一个任务处理步骤时还不错

```js
ajax.get("/test/", function (res) {
  console.log(res);
});
```

但是一旦调用链过长,则需要在这个会调里再次填写回调  
此时著名的回调地狱就出现了

```js
ajax.get("/test/", function (res) {
  console.log(res);
  ajax.get("/test1/", function (res) {
    console.log(res2);
    ajax.get("/test2/", function (res) {
      console.log(res3);
      ajax.get("/test3/", function (res) {
        console.log(res);
      });
    });
  });
});
```

这种方式有以下缺点

1. 嵌套导致的回调地狱
2. 错误处理麻烦
3. 处理并行任务麻烦

这时出现了 es6 新增的 Promise 来解决这个问题

### 2. Promise

Promise 是 JS 内置的一个构造函数,代表承诺的意思  
既然回调有状态,那么就用一个对象来当这个状态的占位符  
 语法

```js
const p = new Promise(function (reslove, reject) {
  ajax(...res(data));
});
```

new 调用 接收一个函数参数,这个函数会**立即执行**  
这个函数会接收两个参数,一个代表成功 reslove, 一个代表失败的 reject
返回值是一个 Promise 对象,默认状态是 pedding 代表未决议  
当异步任务内完成后调用 reslove 函数,此时状态变为成功,  
执行失败调用 reject,在接收这个参数中如何发生错误会直接切换状态为 reject
这俩个函数的参数就是返回的值,可供下面使用
**状态只能改变一次,后续会忽略**

### then 方法

```js
p.then(e => console.log(e));
p.then(e => console.log(e));
p.then(e => console.log(e));
```

返回的对象有一个 then 方法,接收两个回调函数,第一个成功状态的处理函数,第二个为失败状态的处理函数,可以将 then 想象成注册事件回调,**每次调用 then 方法返回一个新的 Promise**  
这个新的 promise 会将传入 then 的参数,和此 Promise 的切换函数封装成上个 promise 的处理函数,也就是说 ,会以上个 promise 的状态为本状态 以上个 promise 处理函数的返回值为值,完成链式调用的特性
如果**这个回调返回一个新的 Promise 则会以这个新的 promise 替换自身**;
例子一:返回值为新的 promise 时

```js
const js = new Promsie(res => {
  res();
});
const a = js.then(e => new Promise(() => {}));
console.log(a); // peddning
```

例子二:返回值非 promise 时

```js
const js = new Promsie(res => {
  res();
});
const a = js.then(e => 123);
console.log(a); // resolve  value:123
```

#### 错误处理

既然有成功状态 自然有失败的状态 失败状态是以 reject 来确认的,执行函数内报错也会触发 reject,使用.catch 的回调来执行,并传入错误对象,同样可以链式调用,并且可以捕获前面所有的错误,如果上一个没有.catch 会链式传递

```js
const Pro = new Promise((res, rej) => {
  rej();
});
Pro.then(() => {})
  .then(() => {})
  .catch(e => {
    console.log(e);
  });
```

此时前面的 then 都不会执行,直接执行 catch 的回调

#### finally

无论成功与否都会执行的回调,不接受参数

#### Promise.all([])

处理并行问题,例如发送 5 个请求,需要等 5 个请求都完成后执行某个函数
有一个失败后就返回失败,其余不再关心

#### Promise.race()

竞赛,以第一个改变的状态为结果,其余的作废

#### Promise.resolve()

返回一个成功的 Promise,参数为返回值

#### Promise.reject()

返回失败 Promise 参数为错误对象

其实 promise 也是传递的回调函数,只不过他解决了嵌套的问题  
变成了链式调用 写法上看着更清晰

### 3. async

es6 新增的生成器函数,给与了函数暂停执行的能力  
配合 Promise 形成了更好的管理异步的方式,所以官方结合这两者出了 async  
就是像写同步代码一样写异步代码;  
语法用下

```js
async function func() {
  const a = await new Promise(res => {
    setTimeOut(() => res(123), 1000);
  });
  console.log(a);
}
```

函数前加一个 async 关键字 此关键字表示此函数会返回一个 Promise  
函数内部可以使用 await(只能用在 async 函数内) 关键字  
表示等待后面的异步操作状态 reslove 后继续返回内部执行,就是当后面的 promise 成功时,  
会将代码下方的任务安排到微任务队列,
并且将返回的值传递回来,供下面继续使用,如果 await 后面不是一个 Promise  
会将这个值直接传递过来(本质是将这个值套一个成功的 promise)
即使是立即完成 也是微任务队列

```js
async function func() {
  const a = await 123;
  console.log(a);
}
name();
console.log(1); //1 123
```

**await 下面的代码块,可以看做是传入 then 的回调函数,也是属于微任务**  
这点不要被误导,因为看起来像是同步代码  
并且这个 async 函数的 reslove 值是 return 的值,如果返回了新的 promise  
则会使用这个新的 promise,这点跟上面是一致的;

```js
async function func() {
  const a = await new Promise((res, rej) => {
    setTimeout(() => {
      res(234);
    }, 1000);
  });
  console.log(a, "func");
  return a;
}
async function func1() {
  const b = await func();
  console.log(b, "func1");
  return b;
}
let res = func1();
res.then(res => console.log(res, "Res"));
```

下面简单概述一下上面执行过程

1. 执行 func1, 执行 await 表达式后面的 func()
2. 进入 func,执行 await 后面代码,然后 func 退出,func 本身返回一个 pedding 的 promise
3. func1 退出,返回一个 pedding 的 promise;
4. 执行 res.then(),注册一个成功时回调
5. 1 秒后,func 内 res 执行,由于 reslove 了,func 恢复执行(本质是另一个微任务),并把 234 传递给 a
6. 执行 log 234,函数执行完毕,将 func 返回的 promise 切换成功,并将返回值 234 传入
7. 由于 func 的成功,func1 继续执行,并将返回值传入 b,
8. 执行 clg (b)
9. func1()执行完毕,并将返回的 promise 置为成功,将 b 传入
10. res 状态为成功,所以执行注册的事件回调,打印 234

整体原则就是,async 本身返回一个 promise,await 监视其后面的 promise 并退出函数,成功时安排下方代码为一个微任务(哪怕返回的是立即成功的 resolve,也是安排微任务),并将 reslove 的值最为 await 的返回值 async return(执行完毕) 会将自身返回的 Promise 置为成功,并将函数的返回值作为 reslove 的值
整体输出顺序是,

1. 234,func
2. 234,func1
3. 234,res

需要注意的是 如果 await 后的 promise reject 了,会直接抛出错误,如果没有捕获,那么这个错误会将 async 函数的结果置为 reject 并且结束函数执行

#### 错误处理

由于 async 没有.catch 方法,所以需要用 try..catch 来解决错误问题  
因为切换到错误状态时,会抛出一个错误,如果不捕获,会直接退出整个函数,并 reject

```js
async function func() {
  try {
    await new Promise((res, rej) => {
      rej();
    });
  } catch (e) {
    console.log(e);
  }
}
func();
```

## 转换老旧方法

新的 api 基本都返回 promise 了,而一些老的方法还是使用的回调的方法,我们可以把他们包装成  
新的异步方式.例如

```js
const pro = await new Promise((res, rej) => {
  oldcallback(res);
});
```

## 总结

普通的回调 属于嵌套调用
Promise 属于链式调用
async await 属于像同步代码一样管理异步 并且可以理解为封装了一系列步骤的重用异步逻辑,方便书写的同时  
也可以完成逻辑复用的效果
